<xacro:macro name="camera_gimbal" params="">

  <!-- Pan joint -->
  <link name="gimbal_pan"/>
  <joint name="gimbal_pan_joint" type="continuous">
    <parent link="base_link"/>
    <child link="gimbal_pan"/>
    <origin xyz="0 0 0.10"/>
    <axis xyz="0 0 1"/>
  </joint>

  <!-- Tilt joint -->
  <link name="gimbal_tilt"/>
  <joint name="gimbal_tilt_joint" type="continuous">
    <parent link="gimbal_pan"/>
    <child link="gimbal_tilt"/>
    <origin xyz="0 0 0.03"/>
    <axis xyz="0 1 0"/>
  </joint>

  <!-- Camera -->
  <link name="camera_link"/>
  <joint name="camera_joint" type="fixed">
    <parent link="gimbal_tilt"/>
    <child link="camera_link"/>
    <origin xyz="0.02 0 0"/>
  </joint>

</xacro:macro>
